Workbook

Sheet 개요
A1: IoT 혁신융합대학 비교과 출석체크 — 요구사항·화면 설계서
A2: 버전 v0.6.1 (구현 내용 반영) · 작성일 2026-10-29 · 관련 문서: docs/usecase.md, docs/architecture.md
A4: 확정된 설계 결정
A5: 서버 | B5: 사무실 PC 1대 + Tailscale Funnel(고정 주소 ○○.ts.net, 도메인·포트 개방 없음) + Docker Compose. 학교 네트워크 사용 허용. 개발 PC와 서버 PC는 별개
A6: 출석 판정 | B6: GPS(건물 범위) + 강의실 코드(4자리, 30초마다 변경)를 함께 사용
A7: 대리출석 방지 | B7: 최초 로그인 기기를 계정에 묶고(기기 쿠키), 같은 수업에서 같은 기기로 두 계정이 출석하면 기기 주인이 아닌 계정을 자동 취소. 불이익: 벌점 / 수료 불가 / 출석 취소
A8: 총관리자 접속 | B8: Tailscale로 연결된 인증 PC에서만 접속 + ID/PW + OTP
A9: 데이터 | B9: PostgreSQL(원본) + Redis(세션 3시간, 요청 횟수). 강의실 코드는 저장하지 않고 30초마다 계산
A10: 인솔자 로그인 | B10: 공동 로그인 화면 → 2차 인증(학교 코드 4자리, 학교별 고정, 총관리자만 변경)
A11: 미등록 기기 | B11: 인솔자 승인 후 출석 인정. 로그 기록 + 담당 인솔자에게 화면 알림·이메일
A12: 출석 규칙 | B12: 시작 5분 전 ~ 5분 후 출석, 이후 종료까지 지각, 종료 후 결석 · GPS 반경 기본 50m
A13: 기술 스택 | B13: TypeScript: React(반응형·PWA) + NestJS · 휴대폰·태블릿·노트북 지원
A14: 출결 변경 | B14: 인솔자는 신청만 하고, 총관리자가 승인·미승인한 뒤 반영
A15: 문의·오류 | B15: 학생 문의 → 인솔자 처리(어려우면 총관리자 이관) / 인솔자 문의 → 총관리자. 모든 기록은 총관리자 열람
A16: 알림 · 보유기간 | B16: 알림은 이메일 · 개인정보는 프로그램 종료 후 1년 뒤 파기
... A23: 코드 저장소 | B23: GitHub 공개 저장소 · 비밀 정보·DB 내용·실제 접속 주소는 올리지 않음
A25: 시트 안내
A26: 기능 요구사항 | B26: 사용자별 기능 요구사항 (ID, 우선순위, 출처, 상태, 관련 유스케이스·화면)
A27: 비기능 요구사항 | B27: 보안, 개인정보, 성능, 가용성, 호환성, 운영, 디자인
A28: 화면 목록 | B28: 전체 화면과 경로(URL), 접속 경로(공개 주소 / Tailscale 전용)
A29: 화면 상세 | B29: 주요 화면의 구성 요소, 표시 내용, 동작 규칙
A30: 엑셀 양식 | B30: 일괄 등록용 업로드 템플릿 컬럼과 출석 로그 다운로드 컬럼
A31: 미확정 사항 | B31: 결정이 필요한 항목. 노란 칸에 결정 내용을 적는다
A33: 범례
A34: 우선순위 | B34: 필수: 1차 오픈에 반드시 포함 · 권장: 가능하면 1차에 포함 · 선택: 이후 추가
A35: 출처 | B35: 사용자 요구: 원래 요구사항 · 결정 사항: 설계 중 확정한 내용 · 추천: 설계 검토 중 제안한 기능
A36: 상태 | B36: 확정: 그대로 진행 · 검토 필요: 제안한 내용으로 검토 대기 · 미확정: 결정이 필요함 ("미확정 사항" 시트 참고)
A37: 입력 칸 | B37: 노란 칸은 직접 입력하는 칸 ("미확정 사항" 시트의 결정 내용)
A39: 기능 요구사항 집계 (자동 계산)
A40: 사용자 | B40: 필수 | C40: 권장 | D40: 선택 | E40: 합계 | F40: 미확정
A41: 학생 | B41: =COUNTIFS('기능 요구사항'!$B$5:$B$64,$A41,'기능 요구사항'!$F$5:$F$64,B$40) -> 15 | C41: =COUNTIFS('기능 요구사항'!$B$5:$B$64,$A41,'기능 요구사항'!$F$5:$F$64,C$40) -> 1 | D41: =COUNTIFS('기능 요구사항'!$B$5:$B$64,$A41,'기능 요구사항'!$F$5:$F$64,D$40) -> 2 | E41: =SUM(B41:D41) -> 18 | F41: =COUNTIFS('기능 요구사항'!$B$5:$B$64,$A41,'기능 요구사항'!$H$5:$H$64,"미확정") -> 0
A42: 인솔자 | B42: =COUNTIFS('기능 요구사항'!$B$5:$B$64,$A42,'기능 요구사항'!$F$5:$F$64,B$40) -> 12 | C42: =COUNTIFS('기능 요구사항'!$B$5:$B$64,$A42,'기능 요구사항'!$F$5:$F$64,C$40) -> 1 | D42: =COUNTIFS('기능 요구사항'!$B$5:$B$64,$A42,'기능 요구사항'!$F$5:$F$64,D$40) -> 0 | E42: =SUM(B42:D42) -> 13 | F42: =COUNTIFS('기능 요구사항'!$B$5:$B$64,$A42,'기능 요구사항'!$H$5:$H$64,"미확정") -> 0
A43: 운영자 공통 | B43: =COUNTIFS('기능 요구사항'!$B$5:$B$64,$A43,'기능 요구사항'!$F$5:$F$64,B$40) -> 2 | C43: =COUNTIFS('기능 요구사항'!$B$5:$B$64,$A43,'기능 요구사항'!$F$5:$F$64,C$40) -> 2 | D43: =COUNTIFS('기능 요구사항'!$B$5:$B$64,$A43,'기능 요구사항'!$F$5:$F$64,D$40) -> 0 | E43: =SUM(B43:D43) -> 4 | F43: =COUNTIFS('기능 요구사항'!$B$5:$B$64,$A43,'기능 요구사항'!$H$5:$H$64,"미확정") -> 0
A44: 총관리자 | B44: =COUNTIFS('기능 요구사항'!$B$5:$B$64,$A44,'기능 요구사항'!$F$5:$F$64,B$40) -> 14 | C44: =COUNTIFS('기능 요구사항'!$B$5:$B$64,$A44,'기능 요구사항'!$F$5:$F$64,C$40) -> 1 | D44: =COUNTIFS('기능 요구사항'!$B$5:$B$64,$A44,'기능 요구사항'!$F$5:$F$64,D$40) -> 2 | E44: =SUM(B44:D44) -> 17 | F44: =COUNTIFS('기능 요구사항'!$B$5:$B$64,$A44,'기능 요구사항'!$H$5:$H$64,"미확정") -> 0
A45: 시스템 | B45: =COUNTIFS('기능 요구사항'!$B$5:$B$64,$A45,'기능 요구사항'!$F$5:$F$64,B$40) -> 7 | C45: =COUNTIFS('기능 요구사항'!$B$5:$B$64,$A45,'기능 요구사항'!$F$5:$F$64,C$40) -> 1 | D45: =COUNTIFS('기능 요구사항'!$B$5:$B$64,$A45,'기능 요구사항'!$F$5:$F$64,D$40) -> 0 | E45: =SUM(B45:D45) -> 8 | F45: =COUNTIFS('기능 요구사항'!$B$5:$B$64,$A45,'기능 요구사항'!$H$5:$H$64,"미확정") -> 0
A46: 합계 | B46: =SUM(B41:B45) -> 50 | C46: =SUM(C41:C45) -> 6 | D46: =SUM(D41:D45) -> 4 | E46: =SUM(E41:E45) -> 60 | F46: =SUM(F41:F45) -> 0
A48: 진행 현황 (자동 계산)
A49: 기능 요구사항 수 | B49: =COUNTA('기능 요구사항'!$A$5:$A$64) -> 60
A50: 비기능 요구사항 수 | B50: =COUNTA('비기능 요구사항'!$A$5:$A$32) -> 28
A51: 화면 수 | B51: =COUNTA('화면 목록'!$A$5:$A$32) -> 28
...

Sheet 기능 요구사항
A1: 기능 요구사항
A2: 사용자: 학생 · 인솔자 · 운영자 공통(인솔자+총관리자) · 총관리자 · 시스템 / 유스케이스 ID는 docs/usecase.md 기준
A4: ID | B4: 사용자 | C4: 기능 영역 | D4: 요구사항명 | E4: 상세 내용 | F4: 우선순위 | G4: 출처 | H4: 상태 | I4: 유스케이스 | J4: 관련 화면 | K4: 비고
A5: STU-01 | B5: 학생 | C5: 로그인 | D5: 학교·학번·이름 로그인 | E5: 학생·인솔자 공동 로그인 화면에서 "학생"을 선택하고, 학교(드롭다운)·학번·이름을 입력한다. 등록된 학생 정보와 일치해야 로그인된다. | F5: 필수 | G5: 사용자 요구 | H5: 확정 | I5: S01 | J5: S-01
A6: STU-02 | B6: 학생 | C6: 로그인 | D6: 사용자 저장 | E6: 체크하면 학교·학번·이름 입력값을 기기에 기억해 다음 방문 때 자동 입력한다. 로그인 세션 자체는 3시간 후 만료된다. | F6: 권장 | G6: 사용자 요구 | H6: 확정 | I6: S01 | J6: S-01 | K6: 자동 로그인과 3시간 만료가 충돌해 "입력값 기억"으로 조정
A7: STU-03 | B7: 학생 | C7: 로그인 | D7: 로그인 유지와 3시간 만료 | E7: 새로고침해도 로그인 정보가 유지되며, 로그인 후 3시간이 지나면 자동으로 만료된다. | F7: 필수 | G7: 사용자 요구 | H7: 확정 | I7: S01, X02 | J7: S-01, S-03 | K7: 세션 길이에 대한 법적 제한 없음
A8: STU-04 | B8: 학생 | C8: 공통 | D8: 상단 사용자 정보 표시 | E8: 로그인 후 화면 상단에 "00대 00과 홍길동(학번)" 형식으로 표시한다. 예: 한국대 컴퓨터공학과 홍길동(20231234) | F8: 필수 | G8: 사용자 요구 | H8: 확정 | I8: S04 | J8: S-03 | K8: 2026-10-28 결정 (소속 먼저)
A9: STU-05 | B9: 학생 | C9: 동의 | D9: 개인정보·위치정보 동의 | E9: 최초 로그인 시 개인정보 수집·이용 동의와 위치정보 이용 동의를 받는다. 동의 이력(일시, 동의서 버전)을 저장한다. | F9: 필수 | G9: 사용자 요구 | H9: 확정 | I9: S02 | J9: S-02 | K9: 위치 동의 거부 시 대체 출석 수단 안내 (NFR-PRV-03)
A10: STU-06 | B10: 학생 | C10: 기기 | D10: 최초 로그인 기기 등록 | E10: 최초 로그인 시 브라우저의 기기 쿠키(서버가 준 임의 값, DB에는 해시만 저장)를 계정에 묶는다. 그 기기가 다른 학생의 등록 기기이면 묶지 않는다. 이후 출석 때마다 같은 기기인지 확인한다. | F10: 필수 | G10: 결정 사항 | H10: 확정 | I10: S03 | J10: S-02 | K10: 2026-10-28 결정 (대리출석 방지)
A11: STU-07 | B11: 학생 | C11: 기기 | D11: 등록되지 않은 기기 처리 | E11: 등록된 기기와 다른 기기로 로그인하면 인솔자 승인이 있어야 출석이 인정된다. 학생 화면에 "등록되지 않은 기기예요"와 빨간 느낌표로 "해당 기기의 아이디가 아니에요"를 표시하고, 경고 문구 "대리 출석의 경우 벌점, 수료 불가, 출석 취소 등 불이익이 있습니다. 같은 기기로 두 계정이 출석하면 기기 주인이 아닌 계정의 출석이 취소됩니다."를 함께 보여준다. 위치·코드 확인 결과는 "기기 승인 대기"로 저장하고, 인솔자가 승인하면 승인한 시각 기준으로 출석 규칙(STU-14)을 적용한다 (수업 종료 후 승인이면 결석 유지, 기기만 등록). 이 기기의 주인이 같은 수업에 출석했거나 다른 계정이 먼저 출석했다면, 승인 대기 없이 바로 출석 취소한다(SYS-08). 로그를 남기고 담당 인솔자에게 화면 알림 + 이메일을 보낸다. | F11: 필수 | G11: 결정 사항 | H11: 확정 | I11: S03, T04 | J11: S-03, L-08 | K11: 2026-10-28 결정. 경고 문구는 사용자 지정 (불이익 내용 반영)
A12: STU-08 | B12: 학생 | C12: 출석 | D12: 날짜 자동 인식 | E12: 출석 날짜는 서버 날짜로 자동 결정되며 사용자가 바꿀 수 없다. 폰 시간이 틀려도 서버 시간 기준으로 판정한다. | F12: 필수 | G12: 사용자 요구 | H12: 확정 | I12: S04 | J12: S-03
A13: STU-09 | B13: 학생 | C13: 출석 | D13: 수업 정보 표시 | E13: 출석 버튼 약간 위에 "0교시 | 과목명"을 표시한다. 출석 전과 후 모두 표시한다. 하루 여러 교시를 들으므로 지금 출석할 수 있는 수업을 기준으로 버튼을 보여주고, 그 아래에 오늘 수업 목록(교시·과목·장소·상태)을 보여준다. | F13: 필수 | G13: 사용자 요구 | H13: 확정 | I13: S04 | J13: S-03 | K13: 요구사항 3-4의 "로그인 전"은 "출석 전"으로 해석. 교시마다 장소가 다를 수 있음
A14: STU-10 | B14: 학생 | C14: 출석 | D14: 출석 버튼 (미출 상태) | E14: 출석 전에는 버튼 가운데 "미출"을 표시한다. 버튼을 누르면 위치 확인과 코드 입력을 진행한다. | F14: 필수 | G14: 사용자 요구 | H14: 확정 | I14: S05 | J14: S-03, S-04
A15: STU-11 | B15: 학생 | C15: 출석 | D15: GPS 위치 확인 | E15: 브라우저 위치 기능으로 현재 좌표를 받아 수업 장소 좌표와의 거리를 계산한다. 허용 반경 안이면 통과한다. 거리와 정확도를 기록한다. | F15: 필수 | G15: 사용자 요구 | H15: 확정 | I15: S06 | J15: S-04 | K15: 브라우저 위치 기능은 무료. 지도 API는 쓰지 않음
A16: STU-12 | B16: 학생 | C16: 출석 | D16: 강의실 코드 입력 | E16: 인솔자가 강의실 화면에 띄운 4자리 숫자 코드(30초마다 변경)를 입력한다. | F16: 필수 | G16: 결정 사항 | H16: 확정 | I16: S07 | J16: S-04 | K16: 2026-10-28 결정 (같은 건물에서 GPS 보완)
A17: STU-13 | B17: 학생 | C17: 출석 | D17: 출석 완료 표시 | E17: 출석이 인정되면 버튼을 비활성화하고 "출석" 문구를 표시한다. | F17: 필수 | G17: 사용자 요구 | H17: 확정 | I17: S05 | J17: S-03, S-05 | K17: 지각이면 "지각" 표시 (STU-14)
A18: STU-14 | B18: 학생 | C18: 출석 | D18: 출석 가능 시간 | E18: 수업 시작 5분 전 ~ 시작 후 5분: 출석 시작 후 5분 ~ 수업 종료: 지각 수업 종료 후: 출석 불가, 자동 결석 (SYS-01) | F18: 필수 | G18: 결정 사항 | H18: 확정 | I18: S05, X01 | J18: S-03 | K18: 2026-10-28 결정
A19: STU-15 | B19: 학생 | C19: 출석 | D19: 실패 원인 안내 | E19: 위치 권한 거부, 반경 밖, 코드 오류·만료, 출석 시간 아님 등 실패 원인별로 메시지와 다음 행동을 안내한다. | F19: 필수 | G19: 추천 | H19: 검토 필요 | I19: S05 | J19: S-05
A20: STU-16 | B20: 학생 | C20: 문의 | D20: 문의·오류 신고 | E20: 모든 학생 화면 상단의 "문의" 버튼과 출석 실패·승인 대기·출석 취소 화면의 링크로 들어간다. 분류를 고르고 내용을 적어 문의한다. 분류: 출석 불가 / 위치 인식 불가 / 코드 입력 불가 / 로그인 불가 / 기기 변경·분실 / 수업 정보 오류 / 기타 기기 정보, 마지막 출석 시도 결과, 앱 버전을 자동으로 함께 보낸다 (좌표 제외). 담당 인솔자가 처리하고, 상태와 답변을 "내 문의"에서 확인한다. | F20: 필수 | G20: 사용자 요구 | H20: 확정 | I20: S08 | J20: S-06 | K20: 2026-10-28 결정. 기존 이의신청을 문의로 통합. 출석 인정이 필요하면 인솔자가 출결 변경 신청(LDR-08)
A21: STU-17 | B21: 학생 | C21: 조회 | D21: 내 출석 내역 | E21: 본인의 날짜별 출석 상태를 조회한다. | F21: 선택 | G21: 추천 | H21: 검토 필요 | I21: - | J21: S-07
A22: STU-18 | B22: 학생 | C22: 공통 | D22: 홈 화면 추가 (PWA) | E22: 앱 설치 없이 홈 화면에 아이콘을 추가해 앱처럼 쓸 수 있다. | F22: 선택 | G22: 추천 | H22: 검토 필요 | I22: - | J22: 전체
A23: LDR-01 | B23: 인솔자 | C23: 로그인 | D23: 공동 로그인 + 학교 코드 2차 인증 | E23: 공동 로그인 화면에서 "담당자"를 선택하고 학교(드롭다운)·직번·이름을 입력한다. 사용자 저장 체크박스를 제공한다. 이어서 2차 인증 화면에서 학교 코드 4자리를 입력한다. 학교 코드는 학교별로 정해지며 자동으로 바뀌지 않는다. | F23: 필수 | G23: 결정 사항 | H23: 확정 | I23: T01 | J23: S-01, L-01 | K23: 2026-10-28 결정. 코드 변경은 총관리자만 (ADM-11)
A24: LDR-02 | B24: 인솔자 | C24: 공통 | D24: 상단 담당자 표시 | E24: 화면 상단에 "00대 담당자: 000님"을 표시한다. | F24: 필수 | G24: 사용자 요구 | H24: 확정 | I24: T01 | J24: L-02 외 전체
A25: LDR-03 | B25: 인솔자 | C25: 출석 현황 | D25: 담당 학교 출석 현황 조회 | E25: 담당 학교 학생의 출석 로그를 표로 보여준다. 컬럼: 학번 | 이름 | 위치 | 날짜 | 참가여부 | 동일기기 의심여부 날짜·수업·상태·검색 필터를 제공한다. | F25: 필수 | G25: 사용자 요구 | H25: 확정 | I25: O01 | J25: L-02
A26: LDR-04 | B26: 인솔자 | C26: 출석 현황 | D26: 출석 요약 | E26: 선택한 날짜·수업의 전체 인원, 출석, 지각, 미출, 의심 인원을 요약 카드로 보여준다. | F26: 권장 | G26: 추천 | H26: 검토 필요 | I26: O01 | J26: L-02
A27: LDR-05 | B27: 인솔자 | C27: 출석 현황 | D27: 동일기기 의심 표시 | E27: 같은 기기로 같은 수업에 2명 이상 출석했거나, 등록되지 않은 기기로 출석한 경우 "의심"으로 표시한다. 같은 기기로 두 계정이 출석하면 기기 주인이 아닌 계정을 시스템이 자동으로 출석 취소한다(SYS-08). 표에는 "대리 출석 · 자동 취소"로 보인다. 정당한 사유가 있으면(예: 휴대폰 고장으로 친구 기기를 빌림) 인솔자가 출결 변경을 신청한다. | F27: 필수 | G27: 사용자 요구 | H27: 확정 | I27: O01 | J27: L-02 | K27: IP만으로는 판단하지 않음. 2026-10-28 결정 (기기 주인 유지, 다른 계정 취소)
A28: LDR-06 | B28: 인솔자 | C28: 출석 현황 | D28: Excel·CSV 다운로드 | E28: 현재 필터 기준의 출석 로그를 Excel(.xlsx) 또는 CSV로 내려받는다. | F28: 필수 | G28: 사용자 요구 | H28: 확정 | I28: O03 | J28: L-02 | K28: 컬럼 정의는 "엑셀 양식" 시트
A29: LDR-07 | B29: 인솔자 | C29: 출석 코드 | D29: 강의실 코드 띄우기 | E29: 선택한 수업의 4자리 코드를 전체 화면으로 띄운다. 30초마다 바뀌며 남은 시간과 출석 인원을 함께 보여준다. | F29: 필수 | G29: 결정 사항 | H29: 확정 | I29: T02 | J29: L-03 | K29: 빔프로젝터·노트북 화면용
A30: LDR-08 | B30: 인솔자 | C30: 출석 관리 | D30: 출결 변경 신청 | E30: 인솔자는 출석 상태를 직접 바꾸지 않고 변경을 신청한다: 학생·수업, 현재 상태 → 변경 후 상태(출석/지각/결석/공결), 사유(필수), 연결된 문의. 총관리자가 승인하면 반영되고, 미승인이면 사유와 함께 돌려받는다. 10분 안에 총관리자가 답하지 않으면 우선 거절된다(SYS-07). 총관리자가 나중에 다시 확인해 승인할 수 있으므로 다시 신청하지 않아도 된다. 신청 내역과 결과는 문의함에서 확인한다. | F30: 필수 | G30: 사용자 요구 | H30: 확정 | I30: O02 | J30: L-04, L-05 | K30: 2026-10-28 결정 (직접 수정 → 신청·승인)
A31: LDR-09 | B31: 인솔자 | C31: 문의 | D31: 학생 문의 처리 | E31: 담당 학교 학생의 문의에 답변하고 해결 처리한다. 해결이 어려우면 총관리자에게 넘긴다(이관). 출석 인정이 필요하면 출결 변경 신청과 연결한다. 새 문의는 화면 알림 + 이메일로 받는다. | F31: 필수 | G31: 사용자 요구 | H31: 확정 | I31: T03 | J31: L-05 | K31: 2026-10-28 결정. 학생 문의 기록은 총관리자도 열람
A32: LDR-10 | B32: 인솔자 | C32: 학생·수강 | D32: 수강 정보 추가·수정·삭제 | E32: 학생의 수강 정보에 오류가 있으면 수업을 추가, 수정, 삭제한다. 변경 이력을 남긴다. | F32: 필수 | G32: 사용자 요구 | H32: 확정 | I32: O05 | J32: L-06 | K32: 2026-10-28 확인 (요구사항 5번)
A33: LDR-11 | B33: 인솔자 | C33: 학생·수강 | D33: 학생 기기 초기화 | E33: 폰 교체·분실 시 학생의 기기 등록을 해제해 새 기기로 다시 등록할 수 있게 한다. | F33: 필수 | G33: 추천 | H33: 검토 필요 | I33: O06 | J33: L-06 | K33: 기기 묶기(STU-06) 도입에 따라 필요
A34: LDR-12 | B34: 인솔자 | C34: 기기 | D34: 미등록 기기 승인 | E34: 학생이 등록되지 않은 기기로 출석하면 화면 알림 배지와 이메일을 받는다. 요청 목록에서 학생, 요청 시각, 기기 정보, 위치·코드 확인 결과를 보고 승인 또는 거절한다. | F34: 필수 | G34: 결정 사항 | H34: 확정 | I34: T04 | J34: L-08 | K34: 2026-10-28 결정. 승인·거절도 로그에 기록
A35: LDR-13 | B35: 인솔자 | C35: 문의 | D35: 총관리자에게 문의·오류 신고 | E35: 인솔자에게 생긴 문제나 해결하지 못한 문제를 총관리자에게 신고한다. 분류: 정보 변경 불가 / 학생 인식 불가 / 엑셀 등록 오류 / 강의실 코드 표시 오류 / 출석 현황·다운로드 오류 / 로그인·학교 코드 문제 / 알림·이메일 미수신 / 기타 | F35: 필수 | G35: 사용자 요구 | H35: 확정 | I35: T05 | J35: L-05 | K35: 2026-10-28 결정. 분류는 제안안
A36: COM-01 | B36: 운영자 공통 | C36: 엑셀 등록 | D36: 학생·수강정보 일괄 등록 | E36: 엑셀을 올려 학생 정보와 수강 정보를 한 번에 등록한다. 순서: 템플릿 다운로드 → 업로드 → 행별 오류 미리보기 → 확정 | F36: 필수 | G36: 사용자 요구 | H36: 확정 | I36: O04 | J36: L-07, A-05 | K36: 인솔자와 총관리자에게 제공
A37: COM-02 | B37: 운영자 공통 | C37: 엑셀 등록 | D37: 업로드 검증과 중복 처리 | E37: 필수값 누락, 형식 오류, 없는 수업, 중복 학번을 행별로 표시한다. 이미 있는 학생은 갱신 또는 건너뛰기 중 선택한다. | F37: 권장 | G37: 추천 | H37: 검토 필요 | I37: O04 | J37: L-07, A-05
A38: COM-03 | B38: 운영자 공통 | C38: 권한 | D38: 데이터 접근 범위 | E38: 인솔자는 담당 학교 데이터만, 총관리자는 모든 학교 데이터를 보고 수정할 수 있다. | F38: 필수 | G38: 사용자 요구 | H38: 확정 | I38: O01~O06 | J38: 전체
A39: COM-04 | B39: 운영자 공통 | C39: 권한 | D39: 수정 이력 기록 | E39: 출석 수정, 엑셀 등록, 기기 초기화 등 운영자 작업을 누가 언제 했는지 기록한다. | F39: 권장 | G39: 추천 | H39: 검토 필요 | I39: O02 | J39: -
A40: ADM-01 | B40: 총관리자 | C40: 접속 | D40: 인증 PC에서만 접속 | E40: Tailscale 사설망에 연결된 인증 PC에서만 관리자 화면이 열린다. 공개 주소(Funnel)로 들어온 /admin 요청은 차단한다. | F40: 필수 | G40: 사용자 요구 | H40: 확정 | I40: A01 | J40: A-01 | K40: "사무실 PC와 인증된 몇몇 PC만" 요구 반영
A41: ADM-02 | B41: 총관리자 | C41: 접속 | D41: ID/PW + OTP 로그인 | E41: 아이디·비밀번호와 OTP 앱(Google Authenticator 등)의 6자리 코드로 로그인한다. | F41: 필수 | G41: 추천 | H41: 검토 필요 | I41: A01 | J41: A-01 | K41: "특별 로그인 방식" 요구에 대한 제안
...

Sheet 비기능 요구사항
A1: 비기능 요구사항
A2: 보안 · 개인정보 · 성능 · 가용성 · 호환성 · 운영 · 디자인
A4: ID | B4: 분류 | C4: 요구사항 | D4: 상세 내용 | E4: 우선순위 | F4: 출처 | G4: 상태 | H4: 비고
A5: NFR-SEC-01 | B5: 보안 | C5: HTTPS 전용 | D5: 모든 접속은 HTTPS로만 한다. 브라우저 위치 기능도 HTTPS에서만 동작한다. 공개 주소는 Tailscale Funnel의 고정 주소(○○.ts.net)를 쓰고 인증서는 자동 발급된다. | E5: 필수 | F5: 결정 사항 | G5: 확정 | H5: 미확정 10번 결정 (2026-10-28)
A6: NFR-SEC-02 | B6: 보안 | C6: 외부 인바운드 포트 없음 | D6: Tailscale(서버가 밖으로만 연결)을 쓰고 공유기 포트를 열지 않는다. 학교 네트워크 사용은 허용됨. | E6: 필수 | F6: 결정 사항 | G6: 확정 | H6: 2026-10-28 학교 확인
A7: NFR-SEC-03 | B7: 보안 | C7: 관리자 화면 이중 차단 | D7: Nginx를 공개 포트(Funnel)와 관리자 포트(Serve, Tailscale 기기만)로 나눈다. 공개 포트의 /admin 요청은 차단하고, 관리자 화면은 관리자 포트로만 연다. | E7: 필수 | F7: 결정 사항 | G7: 확정
A8: NFR-SEC-04 | B8: 보안 | C8: 로그인 시도 제한 | D8: 같은 학번·IP로 짧은 시간에 여러 번 실패하면 일정 시간 차단한다 (Redis). 인솔자 2차 인증(학교 코드)은 5회 실패 시 잠근다. | E8: 필수 | F8: 추천 | G8: 검토 필요 | H8: 학교 코드는 4자리 고정이라 시도 제한이 필수
A9: NFR-SEC-07 | B9: 보안 | C9: 학교 코드 보호 | D9: 학교 코드는 암호화(해시)해 저장하고, 2차 인증 실패와 코드 변경을 모두 기록한다. 유출이 의심되면 총관리자가 즉시 바꾼다. | E9: 필수 | F9: 추천 | G9: 검토 필요
A10: NFR-SEC-05 | B10: 보안 | C10: 중복 출석 방지 | D10: 버튼 연타나 여러 탭에서 동시에 요청해도 출석은 1건만 저장한다 (수업별 DB 잠금 + DB 고유 제약). | E10: 필수 | F10: 추천 | G10: 검토 필요
A11: NFR-SEC-06 | B11: 보안 | C11: 강의실 코드 위조 방지 | D11: 코드는 서버가 수업별로 발급하고 30초 후 만료한다. 캡처해서 공유해도 금방 무효가 된다. | E11: 필수 | F11: 결정 사항 | G11: 확정
A12: NFR-SEC-08 | B12: 보안 | C12: 요청 횟수 제한 | D12: Funnel에는 공격 차단(WAF) 기능이 없으므로 Nginx와 API에서 요청 횟수를 제한한다. 학교 Wi-Fi에서는 여러 학생이 같은 IP로 보일 수 있어 IP 기준은 넉넉하게 두고 계정 기준 제한을 함께 쓴다. | E12: 필수 | F12: 추천 | G12: 검토 필요 | H12: Funnel 결정에 따라 추가
A13: NFR-PRV-01 | B13: 개인정보 | C13: 수집·이용 동의 | D13: 수집 항목(학번, 이름, 소속, 기기정보, 위치 판정 결과, 문의 내용), 목적, 보유기간(종료 후 1년)을 고지하고 동의를 받는다. 대리 출석 불이익(벌점, 수료 불가, 출석 취소)과 기기 주인이 아닌 계정 자동 취소 규칙을 함께 적는다. | E13: 필수 | F13: 추천 | G13: 검토 필요
A14: NFR-PRV-02 | B14: 개인정보 | C14: 위치 정보 최소 저장 | D14: 좌표 원본은 저장하지 않거나 짧게 보관하고, 거리·정확도·판정 결과만 저장한다. | E14: 권장 | F14: 추천 | G14: 검토 필요
A15: NFR-PRV-03 | B15: 개인정보 | C15: 동의 거부 시 대체 수단 | D15: 위치 동의를 거부한 학생의 출석 요청은 "위치 없음"으로 실패한다. 학생이 문의하면 인솔자가 출결 변경을 신청하고 총관리자 승인으로 처리한다. | E15: 권장 | F15: 추천 | G15: 검토 필요
A16: NFR-PRV-04 | B16: 개인정보 | C16: 위치정보법 검토 | D16: 비영리·한시 사업이고 좌표를 저장하지 않으므로 별도 신고 없이 진행한다. 위치정보 이용 동의는 그대로 받는다. | E16: 필수 | F16: 결정 사항 | G16: 확정 | H16: 2026-10-28 사용자 판단
A17: NFR-PRV-05 | B17: 개인정보 | C17: 보유기간 후 파기 | D17: 프로그램 종료 후 1년이 지나면 개인정보와 출석 기록을 파기한다 (SYS-05). 동의서에 보유기간 1년을 적는다. | E17: 필수 | F17: 결정 사항 | G17: 확정 | H17: 2026-10-28 결정
A18: NFR-PER-01 | B18: 성능 | C18: 동시 출석 처리 | D18: 학생 50명이 1~2분 안에 동시에 출석해도 응답 2초 이내. | E18: 필수 | F18: 추천 | G18: 검토 필요 | H18: 수치는 가정값
A19: NFR-AVL-01 | B19: 가용성 | C19: 자동 복구 | D19: 컨테이너 자동 재시작, PC 재부팅 후 자동 로그인과 Docker 자동 시작. | E19: 필수 | F19: 추천 | G19: 검토 필요
A20: NFR-AVL-02 | B20: 가용성 | C20: 전원·업데이트 관리 | D20: UPS 연결, Windows 업데이트 재시작은 새벽으로 지정, 절전 모드 끄기. | E20: 권장 | F20: 추천 | G20: 검토 필요
A21: NFR-AVL-03 | B21: 가용성 | C21: 외부 감시 | D21: 서버 PC 밖에서 5분마다 상태를 확인하고, 이상 시 총관리자에게 이메일을 보낸다 (UptimeRobot). | E21: 권장 | F21: 추천 | G21: 검토 필요
A22: NFR-CMP-01 | B22: 호환성 | C22: 반응형 (모든 기기) | D22: 휴대폰, 태블릿(iPad, 갤럭시 탭), 노트북(갤럭시북 등), PC에서 모두 쓸 수 있는 반응형 화면으로 만든다. 학생·인솔자·관리자 화면 모두 해당. | E22: 필수 | F22: 사용자 요구 | G22: 확정 | H22: 2026-10-28 결정
A23: NFR-CMP-02 | B23: 호환성 | C23: 지원 브라우저 | D23: 최신 Chrome(안드로이드·PC), Safari(iOS·iPadOS), Samsung Internet, Edge. 코드 화면은 빔프로젝터 전체 화면에서도 잘 보이도록 큰 글씨로 만든다. | E23: 필수 | F23: 추천 | G23: 검토 필요
A24: NFR-OPS-01 | B24: 운영 | C24: 실행 환경 통일 | D24: 개발 PC와 서버 PC가 다르므로 Docker Compose로 같은 환경을 구성한다. | E24: 필수 | F24: 결정 사항 | G24: 확정
A25: NFR-OPS-02 | B25: 운영 | C25: 배포 | D25: 개발 PC → GitHub → 서버 PC에서 pull 후 재시작. | E25: 권장 | F25: 추천 | G25: 검토 필요
A26: NFR-OPS-04 | B26: 운영 | C26: 기술 스택 | D26: TypeScript로 통일한다. 화면: React 19.1 + Vite 6(반응형, PWA) / API: NestJS 11 + Prisma 6.19 / DB: PostgreSQL 16 / 캐시: Redis 7 / 실행: Docker Compose + Nginx. | E26: 필수 | F26: 결정 사항 | G26: 확정 | H26: 2026-10-28 결정
A27: NFR-OPS-03 | B27: 운영 | C27: 비용 | D27: 도메인을 사지 않고 무료 서비스만 쓴다 (Tailscale Funnel 주소 사용). AI(Claude API)는 쓰지 않는다. | E27: 필수 | F27: 사용자 요구 | G27: 확정 | H27: 2026-10-28 결정 · 2026-10-29 AI 제외
A28: NFR-OPS-05 | B28: 운영 | C28: 공개 저장소 보안 | D28: 코드는 GitHub 공개 저장소에 올린다. 비밀번호·암호화 키·DB 접속 정보·메일 계정은 .env에만 두고 저장소에서 제외한다(.gitignore, 값이 빈 .env.example만 공개). DB 볼륨·백업·업로드한 엑셀도 제외하고, 테스트 데이터는 가짜 이름만 쓴다. 실제 접속 주소와 학교 코드는 문서에 적지 않는다. 커밋 전에 비밀 정보 검사(gitleaks)를 자동 실행한다. | E28: 필수 | F28: 사용자 요구 | G28: 확정 | H28: 2026-10-29 결정
A29: NFR-OPS-06 | B29: 운영 | C29: 고치기 쉬운 코드 | D29: 관리·수정할 사람이 TypeScript·NestJS에 익숙하지 않으므로 코드에 한국어 주석을 충분히 달고, 설치·실행·자주 하는 작업(학생 등록, 백업 복원, 이메일 변경, 문제 해결)을 README에 순서대로 적는다. | E29: 필수 | F29: 사용자 요구 | G29: 확정 | H29: 2026-10-29 결정
A30: NFR-UI-01 | B30: 디자인 | C30: 키 컬러 | D30: 짙은 남색 #1E3A8A (헤더 #0F1F4D, 호버 #2F5BD3, 연한 배경 #EEF3FF). | E30: 필수 | F30: 사용자 요구 | G30: 확정
A31: NFR-UI-02 | B31: 디자인 | C31: 상태 색상 | D31: 출석 #16A34A, 지각 #D97706, 결석 #DC2626, 미출 #64748B, 의심은 빨간 배지. | E31: 권장 | F31: 추천 | G31: 검토 필요
A32: NFR-UI-03 | B32: 디자인 | C32: 서비스 이름과 로고 | D32: 서비스 이름은 "🎓 IoT 혁신융합대학 비교과 출석체크". 모든 화면 상단에 IoT COSS 로고와 함께 표시한다(로그인, 학생·인솔자·총관리자 상단, 강의실 코드 화면). 로고 원본이 흰 바탕이라 남색 헤더 위에서는 흰 배지에 담는다. | E32: 필수 | F32: 사용자 요구 | G32: 확정 | H32: 2026-10-29 결정

Sheet 화면 목록
A1: 화면 목록
A2: S: 학생 · L: 인솔자 · A: 총관리자 / 관리자 화면(/admin)은 Tailscale로만 접속
A4: 화면 ID | B4: 사용자 | C4: 화면명 | D4: 경로 (URL) | E4: 접속 경로 | F4: 화면 목적 | G4: 주요 구성 | H4: 관련 요구사항 | I4: 비고
A5: S-01 | B5: 학생·인솔자 | C5: 공동 로그인 | D5: /login | E5: 공개 주소 | F5: 학생과 인솔자가 함께 쓰는 로그인 | G5: 학생/담당자 선택, 학교 드롭다운, 학번(직번), 이름, 사용자 저장, 로그인 버튼 | H5: STU-01~03, LDR-01 | I5: 담당자는 로그인 후 L-01로 이동
A6: S-02 | B6: 학생 | C6: 동의·기기 등록 | D6: /consent | E6: 공개 주소 | F6: 최초 로그인 시 동의와 기기 등록 | G6: 개인정보 동의, 위치정보 동의, 위치 권한 요청, 기기 등록 안내 | H6: STU-05, STU-06 | I6: 최초 1회
A7: S-03 | B7: 학생 | C7: 출석 메인 | D7: / | E7: 공개 주소 | F7: 오늘 수업 확인과 출석 | G7: 상단 사용자 정보, 오늘 날짜, "0교시 | 과목명", 출석 버튼(미출/출석) | H7: STU-04, STU-08~10, STU-13~14 | I7: 핵심 화면
A8: S-04 | B8: 학생 | C8: 출석 진행 | D8: (S-03 위 모달) | E8: - | F8: 위치 확인과 코드 입력 | G8: 위치 확인 중 표시, 코드 4자리 입력, 확인 버튼 | H8: STU-11, STU-12
A9: S-05 | B9: 학생 | C9: 출석 결과 | D9: (S-03 위 모달) | E9: - | F9: 성공·실패 결과 안내 | G9: 결과 메시지, 재시도, 이의신청 버튼 | H9: STU-13, STU-15
A10: S-06 | B10: 학생 | C10: 문의·오류 신고 | D10: /support | E10: 공개 주소 | F10: 문의 작성과 내 문의 확인 | G10: 분류 선택, 관련 수업, 내용, 자동 첨부 정보 안내, 보내기, 내 문의 목록(상태·답변) | H10: STU-16 | I10: 이의신청을 통합
A11: S-07 | B11: 학생 | C11: 내 출석 내역 | D11: /history | E11: 공개 주소 | F11: 본인 출석 기록 조회 | G11: 날짜별 상태 목록 | H11: STU-17 | I11: 선택 기능
A12: L-01 | B12: 인솔자 | C12: 2차 인증 (학교 코드) | D12: /staff/verify | E12: 공개 주소 | F12: 인솔자 본인 확인 | G12: 학교 코드 4자리 입력, 확인 버튼, 남은 시도 횟수 | H12: LDR-01, NFR-SEC-04 | I12: 5회 실패 시 잠금
A13: L-02 | B13: 인솔자 | C13: 출석 현황 | D13: /staff | E13: 공개 주소 | F13: 담당 학교 출석 현황 확인 | G13: 상단 담당자 표시, 필터, 요약 카드, 출석 로그 표, 다운로드, 코드 띄우기 | H13: LDR-02~06 | I13: 핵심 화면
A14: L-03 | B14: 인솔자 | C14: 강의실 코드 화면 | D14: /staff/code/{수업ID} | E14: 공개 주소 | F14: 강의실 화면에 출석 코드 표시 | G14: 수업명, 큰 4자리 코드, 남은 시간, 출석 인원 | H14: LDR-07 | I14: 전체 화면
A15: L-04 | B15: 인솔자 | C15: 출결 변경 신청 | D15: (L-02·L-05 위 모달) | E15: - | F15: 출결 변경 신청 | G15: 학생·수업, 현재 상태, 변경 후 상태, 사유(필수), 신청 | H15: LDR-08 | I15: 총관리자 승인 후 반영
A16: L-05 | B16: 인솔자 | C16: 문의함 | D16: /staff/support | E16: 공개 주소 | F16: 학생 문의 처리, 총관리자 문의, 변경 신청 내역 | G16: 탭(학생 문의·내 문의·출결 변경 신청 내역), 문의 목록, 상세(자동 첨부 정보), 답변, 해결, 총관리자에게 넘기기, 출결 변경 신청, 총관리자 문의 작성 | H16: LDR-08, LDR-09, LDR-13 | I16: 메뉴에 미처리 수 배지
A17: L-06 | B17: 인솔자 | C17: 학생·수강 관리 | D17: /staff/students | E17: 공개 주소 | F17: 학생별 수강 정보와 기기 관리 | G17: 학생 목록, 수업 추가·수정, 기기 초기화 | H17: LDR-10, LDR-11
A18: L-07 | B18: 인솔자 | C18: 엑셀 일괄 등록 | D18: /staff/import | E18: 공개 주소 | F18: 학생·수강정보 일괄 등록 | G18: 템플릿 다운로드, 업로드, 미리보기, 중복 처리 선택, 확정 | H18: COM-01, COM-02 | I18: 담당 학교만
A19: L-08 | B19: 인솔자 | C19: 기기 승인 요청 | D19: /staff/devices | E19: 공개 주소 | F19: 미등록 기기 출석 승인 | G19: 요청 목록(학생, 요청 시각, 기기 정보, 위치·코드 결과), 승인·거절, 처리 이력 | H19: LDR-12, STU-07 | I19: 메뉴에 알림 배지 표시
A20: A-00 | B20: 총관리자 | C20: 첫 설정 | D20: /admin/setup | E20: Tailscale 전용 | F20: 서버를 처음 켰을 때 한 번만 하는 설정 | G20: 총관리자 계정·비밀번호, OTP 등록(QR), 이메일 발송 계정(SMTP), 테스트 메일 보내기 | H20: ADM-16 | I20: 총관리자가 아직 없을 때만 열림
A21: A-01 | B21: 총관리자 | C21: 관리자 로그인 | D21: /admin/login | E21: Tailscale 전용 | F21: 관리자 로그인 | G21: 아이디, 비밀번호, OTP 6자리 | H21: ADM-01, ADM-02
A22: A-02 | B22: 총관리자 | C22: 전체 출석 현황 | D22: /admin/attendance | E22: Tailscale 전용 | F22: 모든 학교 출석 현황 | G22: L-02와 같은 구성 + 학교 필터 | H22: ADM-03 | I22: L-02 재사용
A23: A-03 | B23: 총관리자 | C23: 학교·인솔자 계정 관리 | D23: /admin/accounts | E23: Tailscale 전용 | F23: 학교·인솔자 계정과 학교 코드 관리 | G23: 학교 목록, 학교 코드(4자리) 발급·변경, 인솔자 목록(이메일 포함), 추가·수정·비활성화, 권한 | H23: ADM-04, ADM-11
A24: A-04 | B24: 총관리자 | C24: 장소·일정 관리 | D24: /admin/sessions | E24: Tailscale 전용 | F24: 수업 장소와 일정 관리 | G24: 장소(좌표·반경) 목록, 수업 일정(날짜·교시·시간·장소) 목록 | H24: ADM-05, ADM-06
A25: A-05 | B25: 총관리자 | C25: 엑셀 일괄 등록 | D25: /admin/import | E25: Tailscale 전용 | F25: 학생·수강정보 일괄 등록 | G25: L-07과 같은 구성 + 학교 선택 | H25: COM-01, COM-02 | I25: L-07 재사용
A26: A-06 | B26: 총관리자 | C26: 장애 현황 | D26: /admin/health | E26: Tailscale 전용 | F26: 서비스 상태 확인 | G26: 상태 카드(API·DB·Redis·Funnel·디스크·백업), 최근 오류, 이메일 알림 이력 | H26: ADM-07 | I26: AI 분석은 하지 않음 (2026-10-29)
A27: A-07 | B27: 총관리자 | C27: 백업 관리 | D27: /admin/backups | E27: Tailscale 전용 | F27: 백업 확인과 복원 | G27: 백업 목록, 성공 여부, 수동 백업, 복원 | H27: ADM-10
A28: A-08 | B28: 총관리자 | C28: 관리자 대시보드 | D28: /admin | E28: Tailscale 전용 | F28: 오늘 상황을 한눈에 보고 바로 처리 | G28: 요약 카드(출석률·변경 승인 대기·재검토 대기·관리자 처리 문의·대리 출석·기기 승인·시스템 상태), 출결 변경 승인 목록(남은 시간), 관리자가 처리할 문의, 학교별 현황 | H28: ADM-14, ADM-12, ADM-13 | I28: 로그인 후 첫 화면
A29: A-09 | B29: 총관리자 | C29: 출결 변경 승인 | D29: /admin/change-requests | E29: Tailscale 전용 | F29: 출결 변경 신청 처리 | G29: 탭(승인 대기·재검토 대기·처리 완료), 신청 목록(학교·학생·수업·변경 전→후·사유·연결 문의·남은 시간), 승인·미승인(사유), 처리 이력 | H29: ADM-12, SYS-07 | I29: 10분 넘으면 재검토 대기로 이동
A30: A-10 | B30: 총관리자 | C30: 문의·오류 관리 | D30: /admin/support | E30: Tailscale 전용 | F30: 이관 문의·인솔자 문의 처리와 전체 기록 | G30: 필터(학교·분류·상태·작성자), 목록, 상세, 답변, 해결 | H30: ADM-13
A31: A-11 | B31: 총관리자 | C31: 대리 출석·불이익 | D31: /admin/penalties | E31: Tailscale 전용 | F31: 대리 출석 건 확인과 불이익 처리 | G31: 대리 출석 건 목록(기기·기기 주인/취소된 계정·수업·자동 취소), 학생별 누적 벌점·수료 불가, 불이익 주기(벌점·수료 불가), 해제 | H31: ADM-15, SYS-08
A32: A-12 | B32: 총관리자 | C32: 설정 | D32: /admin/settings | E32: Tailscale 전용 | F32: 운영 설정 변경 | G32: 이메일 발송 계정 변경, 테스트 메일 (비밀번호는 ••• 표시) | H32: ADM-17

Sheet 화면 상세
A1: 화면 상세 (주요 화면)
A2: 영역: 상단 · 본문 · 하단 · 필터 · 요약 · 단계 · 상태(특정 상황에서 보이는 내용)
A4: 화면 ID | B4: 화면명 | C4: 영역 | D4: 구성 요소 | E4: 유형 | F4: 표시 내용·예시 | G4: 동작·규칙 | H4: 관련 요구사항
A5: S-01 | B5: 공동 로그인 | C5: 상단 | D5: 서비스 이름·로고 | E5: 로고 + 텍스트 | F5: IoT COSS 로고 / 🎓 IoT 혁신융합대학 비교과 출석체크 | G5: 두 줄로 표시 | H5: NFR-UI-03
A6: S-01 | B6: 공동 로그인 | C6: 본문 | D6: 사용자 구분 | E6: 탭 2개 | F6: 학생 · 담당자 | G6: 기본값 학생. 사용자 저장 시 마지막 선택 기억 | H6: STU-01, LDR-01
A7: S-01 | B7: 공동 로그인 | C7: 본문 | D7: 학교 | E7: 드롭다운 | F7: 한국대 / 미래대 … | G7: 필수 선택. 사용자 저장 시 자동 선택 | H7: STU-01, LDR-01
A8: S-01 | B8: 공동 로그인 | C8: 본문 | D8: 학번 / 직번 | E8: 입력 | F8: 20231234 | G8: 필수. 탭에 따라 이름표가 "학번" 또는 "직번"으로 바뀜 | H8: STU-01, LDR-01
A9: S-01 | B9: 공동 로그인 | C9: 본문 | D9: 이름 | E9: 입력 | F9: 홍길동 | G9: 필수 | H9: STU-01, LDR-01
A10: S-01 | B10: 공동 로그인 | C10: 본문 | D10: 사용자 저장 | E10: 체크박스 | F10: 사용자 저장 | G10: 체크 시 입력값을 기기에 기억 | H10: STU-02
A11: S-01 | B11: 공동 로그인 | C11: 본문 | D11: 로그인 | E11: 버튼 (키 컬러) | F11: 로그인 | G11: 학생: 최초 로그인이면 S-02, 아니면 S-03 / 담당자: L-01(2차 인증) | H11: STU-01, LDR-01
A12: S-01 | B12: 공동 로그인 | C12: 상태 | D12: 로그인 실패 | E12: 오류 메시지 | F12: 등록되지 않은 정보입니다. 담당자에게 문의하세요. | H12: STU-01
A13: S-01 | B13: 공동 로그인 | C13: 상태 | D13: 다른 기기 로그인 (학생) | E13: 안내 메시지 | F13: 등록되지 않은 기기입니다. 출석은 담당자 승인 후 인정됩니다. | G13: 로그인은 허용. 담당 인솔자에게 화면 알림 + 이메일 발송, 로그 기록 | H13: STU-07
A14: S-06 | B14: 문의·오류 신고 | C14: 본문 | D14: 분류 | E14: 선택 버튼 7개 | F14: 출석 불가 · 위치 인식 불가 · 코드 입력 불가 · 로그인 불가 · 기기 변경·분실 · 수업 정보 오류 · 기타 | G14: 하나 선택 필수. 실패 화면에서 오면 자동 선택 | H14: STU-16
A15: S-06 | B15: 문의·오류 신고 | C15: 본문 | D15: 관련 수업 / 내용 | E15: 드롭다운 / 입력 | F15: 1교시 AI 기초 (오늘 10:00) | G15: 내용 필수 | H15: STU-16
A16: S-06 | B16: 문의·오류 신고 | C16: 본문 | D16: 함께 보내는 정보 | E16: 안내 상자 | F16: 기기 정보 · 마지막 출석 시도 결과 · 앱 버전 (좌표 제외) | G16: 자동 첨부 | H16: STU-16
A17: S-06 | B17: 문의·오류 신고 | C17: 하단 | D17: 내 문의 | E17: 목록 | F17: 분류 · 상태(접수 / 처리 중 / 해결됨 / 관리자 이관) · 답변 | H17: STU-16
A18: L-01 | B18: 2차 인증 (학교 코드) | C18: 본문 | D18: 안내 | E18: 텍스트 | F18: 한국대 김담당님, 학교 코드 4자리를 입력하세요. | H18: LDR-01
A19: L-01 | B19: 2차 인증 (학교 코드) | C19: 본문 | D19: 학교 코드 | E19: 입력 (숫자 4자리, 가림) | F19: •••• | G19: 학교별 고정 코드. 총관리자가 발급·변경 | H19: LDR-01, ADM-11
A20: L-01 | B20: 2차 인증 (학교 코드) | C20: 본문 | D20: 확인 | E20: 버튼 (키 컬러) | F20: 확인 | G20: 맞으면 L-02로 이동 | H20: LDR-01
A21: L-01 | B21: 2차 인증 (학교 코드) | C21: 상태 | D21: 코드 오류 | E21: 오류 메시지 | F21: 학교 코드가 맞지 않습니다. (남은 시도 3회) | G21: 5회 실패 시 일정 시간 잠금, 기록 | H21: NFR-SEC-04
A22: S-02 | B22: 동의·기기 등록 | C22: 본문 | D22: 개인정보 수집·이용 동의 | E22: 체크박스 + 전문 보기 | F22: 수집 항목, 목적, 보유기간 | G22: 필수 | H22: STU-05
A23: S-02 | B23: 동의·기기 등록 | C23: 본문 | D23: 위치정보 이용 동의 | E23: 체크박스 + 전문 보기 | F23: 출석 장소 확인에만 사용 | G23: 필수. 거부 시 대체 출석 방법 안내 | H23: STU-05
A24: S-02 | B24: 동의·기기 등록 | C24: 본문 | D24: 기기 등록 안내 | E24: 텍스트 | F24: 이 기기가 출석 기기로 등록됩니다. | H24: STU-06
A25: S-02 | B25: 동의·기기 등록 | C25: 본문 | D25: 동의하고 시작 | E25: 버튼 | F25: 동의하고 시작 | G25: 두 항목 모두 체크해야 활성. 누르면 브라우저 위치 권한 요청 후 S-03으로 이동 | H25: STU-05, STU-06
A26: S-03 | B26: 출석 메인 | C26: 상단 | D26: 로고 · 문의 · 로그아웃 | E26: 로고 + 버튼 2개 | F26: IoT COSS 로고 · IoT 혁신융합대학 비교과 출석체크 / 문의 / 로그아웃 | G26: "문의"를 누르면 S-06. 모든 학생 화면 상단에 같은 줄을 둔다. 그 아래 줄에 소속·이름 | H26: STU-16, NFR-UI-03
A27: S-03 | B27: 출석 메인 | C27: 상단 | D27: 사용자 정보 | E27: 텍스트 | F27: 한국대 컴퓨터공학과 홍길동(20231234) | H27: STU-04
A28: S-03 | B28: 출석 메인 | C28: 상단 | D28: 로그아웃 | E28: 버튼 | F28: 로그아웃
A29: S-03 | B29: 출석 메인 | C29: 본문 | D29: 오늘 날짜 | E29: 텍스트 | F29: 2026.11.03 (화) | G29: 서버 날짜. 변경 불가 | H29: STU-08
A30: S-03 | B30: 출석 메인 | C30: 본문 | D30: 수업 정보 | E30: 텍스트 | F30: 1교시 | AI 기초 | G30: 출석 버튼 약간 위. 출석 전·후 모두 표시 | H30: STU-09
A31: S-03 | B31: 출석 메인 | C31: 본문 | D31: 출석 버튼 (출석 전) | E31: 원형 큰 버튼 | F31: 미출 | G31: 출석 가능 시간에만 활성. 누르면 S-04 | H31: STU-10
A32: S-03 | B32: 출석 메인 | C32: 본문 | D32: 출석 버튼 (출석 후) | E32: 원형 버튼 (비활성) | F32: 출석 (지각이면 "지각") | G32: 다시 누를 수 없음 | H32: STU-13
A33: S-03 | B33: 출석 메인 | C33: 본문 | D33: 출석 가능 시간 | E33: 텍스트 | F33: 09:55 ~ 10:05 출석 · 이후 지각 | G33: 시작 5분 전 ~ 5분 후 출석, 이후 종료까지 지각 | H33: STU-14
A34: S-03 | B34: 출석 메인 | C34: 본문 | D34: 오늘 수업 목록 | E34: 목록 | F34: 1교시 AI 기초 (공학관 301) 출석 / 3교시 데이터 분석 (본관 105) 미출 | G34: 하루 여러 교시. 교시마다 장소가 다를 수 있음 | H34: STU-09
A35: S-03 | B35: 출석 메인 | C35: 하단 | D35: 문의하기 | E35: 링크 | F35: 출석이 안 되나요? 문의하기 | G35: S-06으로 이동 | H35: STU-16
A36: S-03 | B36: 출석 메인 | C36: 상태 | D36: 기기 승인 대기 | E36: 버튼(비활성) + 빨간 느낌표 + 경고 | F36: 등록되지 않은 기기예요 / (!) 해당 기기의 아이디가 아니에요 / 대리 출석의 경우 벌점, 수료 불가, 출석 취소 등 불이익이 있습니다. 같은 기기로 두 계정이 출석하면 기기 주인이 아닌 계정의 출석이 취소됩니다. | G36: 미등록 기기로 출석한 경우. 승인되면 승인 시각 기준으로 출석·지각 판정 | H36: STU-07
A37: S-03 | B37: 출석 메인 | C37: 상태 | D37: 출석 취소 (대리 출석) | E37: 버튼(비활성, 빨강) + 빨간 느낌표 + 문의 링크 | F37: 출석이 취소되었어요 / (!) 같은 기기로 다른 계정이 출석했어요 / 대리 출석은 벌점이나 수료 불가 처리될 수 있습니다. 잘못된 경우 문의해 주세요. | G37: 기기 주인이 아닌 계정으로 출석했는데, 기기 주인이나 다른 계정이 같은 기기로 출석한 경우 (SYS-08). 승인 대기 중이었다면 이 상태로 바뀜. 문의하기 → S-06 | H37: SYS-08, STU-16
A38: S-03 | B38: 출석 메인 | C38: 상태 | D38: 오늘 수업 없음 | E38: 안내 메시지 | F38: 오늘 예정된 수업이 없습니다. | G38: 출석 버튼 숨김
A39: S-03 | B39: 출석 메인 | C39: 상태 | D39: 세션 만료 | E39: 안내 후 이동 | F39: 로그인 시간이 만료되었습니다. | G39: 로그인 3시간 후 S-01로 이동 | H39: STU-03
A40: S-04 | B40: 출석 진행 | C40: 1단계 | D40: 위치 확인 중 | E40: 로딩 | F40: 위치를 확인하고 있습니다… | G40: 브라우저 위치 → 서버에서 거리 판정 | H40: STU-11
A41: S-04 | B41: 출석 진행 | C41: 2단계 | D41: 강의실 코드 | E41: 입력 (숫자 4자리) | F41: 강의실 화면의 숫자 4자리를 입력하세요 | G41: 30초마다 바뀌는 코드와 비교 | H41: STU-12
...

Sheet 엑셀 양식
A1: 엑셀 양식
A2: 일괄 등록 템플릿(학생·수강: L-07, A-05 / 인솔자·장소·수업 일정: 총관리자)과 출석 로그 다운로드(L-02, A-02)의 컬럼 정의. 학교(4~5곳)와 학교 코드는 화면(A-03)에서 직접 입력
A4: ① 업로드 템플릿 — "학생" 시트
A5: 컬럼명 | B5: 필수 | C5: 형식 | D5: 예시 | E5: 검증 규칙
A6: 학교 | B6: 필수 | C6: 등록된 학교명 | D6: 한국대 | E6: 학교 목록에 있어야 함. 인솔자는 본인 학교만 가능
A7: 학번 | B7: 필수 | C7: 텍스트 | D7: 20231234 | E7: 같은 학교 안에서 중복 불가. 앞자리 0 유지를 위해 텍스트로 저장
A8: 이름 | B8: 필수 | C8: 텍스트 | D8: 홍길동
A9: 단과대 | B9: 필수 | C9: 텍스트 | D9: 공과대학
A10: 학과 | B10: 필수 | C10: 텍스트 | D10: 컴퓨터공학과
A12: ② 업로드 템플릿 — "수강" 시트
A13: 컬럼명 | B13: 필수 | C13: 형식 | D13: 예시 | E13: 검증 규칙
A14: 학번 | B14: 필수 | C14: 텍스트 | D14: 20231234 | E14: "학생" 시트 또는 이미 등록된 학생이어야 함
A15: 과목명 | B15: 필수 | C15: 텍스트 | D15: AI 기초 | E15: 등록된 수업 일정(A-04)에 있어야 함
A16: 날짜 | B16: 선택 | C16: YYYY-MM-DD | D16: 2026-11-05 | E16: 비우면 그 과목의 모든 회차를 수강. 특정 회차만 들을 때만 적음
A17: 교시 | B17: 선택 | C17: 숫자 | D17: 1 | E17: 날짜를 적었으면 함께 적음
A19: ③ 총관리자용 템플릿 — "인솔자" 시트
A20: 컬럼명 | B20: 필수 | C20: 형식 | D20: 예시 | E20: 검증 규칙
A21: 학교 | B21: 필수 | C21: 등록된 학교명 | D21: 한국대 | E21: 학교 목록에 있어야 함
A22: 직번 | B22: 필수 | C22: 텍스트 | D22: S2024001 | E22: 같은 학교 안에서 중복 불가. 로그인할 때 씀
A23: 이름 | B23: 필수 | C23: 텍스트 | D23: 김담당
A24: 이메일 | B24: 필수 | C24: 이메일 주소 | D24: kim@example.ac.kr | E24: 기기 승인 요청·문의 알림을 받음
A25: 권한 | B25: 선택 | C25: 보기 / 수정 | D25: 수정 | E25: 비우면 수정
A27: ④ 총관리자용 템플릿 — "장소" 시트
A28: 컬럼명 | B28: 필수 | C28: 형식 | D28: 예시 | E28: 검증 규칙
A29: 장소명 | B29: 필수 | C29: 텍스트 | D29: 공학관 301 | E29: 중복 불가. "수업 일정" 시트에서 이 이름으로 찾음
A30: 위도 | B30: 필수 | C30: 숫자 (소수 6자리) | D30: 37.123456 | E30: 지도 앱에서 강의실 건물을 길게 눌러 복사
A31: 경도 | B31: 필수 | C31: 숫자 (소수 6자리) | D31: 127.123456
A32: 허용 반경 | B32: 선택 | C32: 숫자 (m) | D32: 50 | E32: 비우면 50
A34: ⑤ 총관리자용 템플릿 — "수업 일정" 시트 (장소 시트 다음에 올림)
A35: 컬럼명 | B35: 필수 | C35: 형식 | D35: 예시 | E35: 검증 규칙
A36: 과목명 | B36: 필수 | C36: 텍스트 | D36: AI 기초 | E36: 처음 나오는 과목은 자동으로 등록
A37: 날짜 | B37: 필수 | C37: YYYY-MM-DD | D37: 2026-11-05
A38: 교시 | B38: 필수 | C38: 숫자 | D38: 1 | E38: 과목·날짜·교시 조합은 중복 불가
A39: 시작 시각 | B39: 필수 | C39: HH:MM | D39: 10:00 | E39: 출석 가능 시간은 자동 계산 (시작 5분 전 ~ 5분 후)
A40: 종료 시각 | B40: 필수 | C40: HH:MM | D40: 11:50 | E40: 시작 시각보다 늦어야 함
A41: 장소명 | B41: 필수 | C41: 텍스트 | D41: 공학관 301 | E41: "장소" 시트에 있어야 함
A43: ⑥ 출석 로그 다운로드 컬럼 (Excel · CSV 공통)
A44: 컬럼명 | B44: 순서 | C44: 예시 | D44: 구분 | E44: 내용
A45: 학번 | B45: 1 | C45: 20231234 | D45: 사용자 지정 | E45: 학생 학번
A46: 이름 | B46: 2 | C46: 홍길동 | D46: 사용자 지정 | E46: 학생 이름
...

Sheet 미확정 사항
A1: 미확정 사항
A2: 결정이 나면 노란 칸(결정 내용)에 적고 상태를 "결정"으로 바꾼다. 개요 시트의 남은 항목 수가 자동으로 줄어든다. 학교 등 외부 확인이 필요한 항목은 "확인 대기".
A3: 입력 칸
A5: 번호 | B5: 항목 | C5: 현재 상태·제안 | D5: 관련 요구사항 | E5: 확인 대상 | F5: 결정 내용 (입력) | G5: 상태
A6: 1 | B6: 참여 학교 수 | C6: 학교 수에 따라 인솔자 계정 수(학교당 3명 이상)가 정해짐 | D6: ADM-04 | E6: 사업 담당 | F6: 4~5곳 (인솔자 계정 약 12~15개) | G6: 결정
A7: 2 | B7: 인솔자 요구사항 5번 | C7: 원문이 "수업 추가 혹은…"에서 끊김 | D7: LDR-10 | E7: 요구사항 작성자 | F7: 수강 정보 추가·수정·삭제 모두 가능, 변경 이력 기록 | G7: 결정
A8: 3 | B8: 하루 여러 교시 / 회차별 장소 | C8: 여러 교시면 "지금 출석할 수업" 기준으로 표시 | D8: STU-09, ADM-06 | E8: 사업 담당 | F8: 하루 여러 교시, 교시마다 장소가 다를 수 있음 → 수업마다 장소 지정 | G8: 결정
A9: 4 | B9: 등록되지 않은 기기 로그인 정책 | C9: 차단 / 허용+의심 / 인솔자 승인 중 선택 | D9: STU-07, LDR-12 | E9: 사업 담당 | F9: 인솔자 승인 후 출석 인정. 로그 기록 + 담당 인솔자에게 화면 알림·이메일. 출석 판정은 승인 시각 기준 | G9: 결정
A10: 5 | B10: 학생 상단 표시 형식 | C10: 1-1 형식과 3 형식이 다름 | D10: STU-04 | E10: 요구사항 작성자 | F10: 소속 먼저: "한국대 컴퓨터공학과 홍길동(20231234)" | G10: 결정
A11: 6 | B11: 인솔자 로그인 보안 | C11: 직번+이름만으로는 다른 사람이 접속할 수 있음 | D11: LDR-01, ADM-11 | E11: 사업 담당 | F11: 공동 로그인 후 2차 인증으로 학교 코드 4자리 입력. 학교별 고정, 총관리자만 변경 | G11: 결정
A12: 7 | B12: 출석 가능 시간 · 지각 기준 | C12: 몇 분 전·후까지 출석으로 볼지 | D12: STU-14, SYS-01 | E12: 사업 담당 | F12: 시작 5분 전 ~ 5분 후 출석, 이후 수업 종료까지 지각, 종료 후 결석 | G12: 결정
A13: 8 | B13: GPS 허용 반경 | C13: 실내 오차와 엄격함 사이 선택 | D13: STU-11, ADM-05 | E13: 사업 담당 | F13: 기본 50m, 장소별 조정 가능 (현장 테스트 후 재조정) | G13: 결정
A14: 9 | B14: 기술 스택 | C14: API 서버·화면 프레임워크 선택 | D14: NFR-OPS-04 | E14: 개발팀 | F14: TypeScript: React(반응형·PWA) + NestJS. 휴대폰·태블릿·노트북 모두 지원 | G14: 결정
A15: 10 | B15: 도메인 · 접속 주소 | C15: 학교 하위 도메인 사용 불가, 도메인은 사지 않기로 함. Cloudflare Tunnel은 도메인이 있어야 고정 주소를 쓸 수 있음 | D15: NFR-SEC-01~03, NFR-SEC-08 | E15: 사업 담당 | F15: Tailscale Funnel 고정 주소(○○.ts.net) 사용. 관리자 화면은 Tailscale 사설망에서만. 학생에게는 QR 코드 + 홈 화면 추가로 안내. 첫 수업 전 학교 Wi-Fi·LTE 접속과 동시 출석 시험 | G15: 결정
A16: 11 | B16: 알림 채널 | C16: 인솔자 연락과 총관리자 장애 알림 방법 | D16: SYS-04, SYS-06 | E16: 총관리자 | F16: 인솔자: 화면 알림 + 이메일 / 총관리자 장애 알림: 이메일 | G16: 결정
A17: 12 | B17: 위치정보법 신고 여부 | C17: 위치기반서비스사업 신고 대상인지 | D17: NFR-PRV-04 | E17: 사업 담당 | F17: 비영리·한시 사업, 좌표 미저장 → 별도 신고 없이 진행 (동의는 받음) | G17: 결정
... A27: 22 | B27: 운영 시작일 | C27: 첫 수업 날짜 | D27: - | E27: 사업 담당 | F27: 2026-11-05 | G27: 결정
A28: 23 | B28: 수강 범위 | C28: 모든 학생이 모든 수업을 듣는지, 학교·학생마다 듣는 수업이 다른지에 따라 "수강" 시트 작성량이 달라짐 | D28: COM-01 | E28: 사업 담당 | G28: 미결정
